Workbook

Sheet 업무리스트
B1: 업무리스트
B2: 원본: '루틴 업무 설명_26.01 이후' 시트 전체(93건) + '업무 설명_26.01 이전' 시트 중 중복되지 않는 항목(13건). 채용·입사 / 이사·법인등기 프로세스는 별도 시트 참고.
B3: 예상 소요시간: 업무 내용·빈도를 기준으로 1회 수행 시 담당자 1인의 작업 시간을 추정한 값(노란 칸). 외부 처리·대기 기간은 제외했으며 실제 수행 후 조정 필요.
B4: 업무 진행상태 / 중요도 / 업무 분야 / 빈도는 드롭다운으로 선택 가능 ('분류 목록' 시트에서 항목 수정). 시작·마감 날짜는 yyyy-mm-dd 형식.
B5: 비고 = 수행일자 + 원본의 변경 사항/비고, 메모 = 원본의 참고 문서 위치.
B7: 업무 분야 | C7: 업무 빈도 구분 | D7: 업무명 | E7: 업무 내용 | F7: 예상 소요시간 | G7: 업무 진행상태 | H7: 진행 중 / 결과 | I7: 시작 날짜 | J7: 마감 날짜 | K7: 중요도 | L7: 비고 | M7: 메모
B8: 경영지원 | C8: 비정기 | D8: 사무실 외부 고객/방문자 응대 및 안내 | E8: 대표님 요청 시 회의실 안내 및 음료 제공 | F8: 20~30분 / 회
B9: 경영지원 | C9: 비정기 | D9: 법인 서류 업로드 및 관리 | E9: 사업자등록증 등기부등본 통장사본 등 업데이트된 부분이 있으면 채널에 맞춰 파일 업로드 소프트웨어사업자 확인증 - 기한은 1년, 유효기간은 1개월 단위라 유의 | F9: 30분 / 회 | M9: 참고: 경영지원 채널 서류 분류 관련
B10: 경영지원 | C10: 비정기 | D10: 보험증권 가입 | E10: 대표님 요청 시, 매뉴얼 참고해서 발급 서울보증보험 담당자에게 문의하고 메일로 관련 서류 발송 -> sgi 사이트에 들어가면 승인 내역이 있고, 해당 내용 확인하고 보험료 결제하면 사이트 내에서 발급 & 메일로 서류 확인 가능 | F10: 1~2시간 / 건 (담당자 회신 대기 별도) | M10: 참고: 보증보험증권 가입 메뉴얼_24.09.04.xlsx
B11: 경영지원 | C11: 비정기 | D11: 이사 및 인원 변경 시, 법인 등기 임원 변경 | E11: 법무소 비용 및 절차 문의 -> 대표님 확인 및 진행 여부 확인 -> 진행 | F11: 2~3시간 / 건 (법무사 처리기간 1~2주 별도) | L11: 26.01.08 더스마트 통해 진행한 히스토리 추가하기 | M11: 참고: 법인 임원 변경 관련 확인요청_25.06.12.xlsx
B12: 경영지원 | C12: 비정기 | D12: 전자인지 발급 | E12: 공공기관/유사 기관과 계약 체결 시, 전자인지를 발급 받아야 함 전자인지 발급 매뉴얼 (간단) - 전자인지 사이트 들어가서 결제 | F12: 20~30분 / 건 | L12: 수행일자: 필요시
B13: 경영지원 | C13: 일간 | D13: 이 업무리스트 관리 | E13: 일간 업무, 주간 업무 월간 업무 확인하며 누락 없는지 체크 추가 업무 발생할 때마다 지체없이 추가 | F13: 10분 / 일
B14: 경영지원 | C14: 비정기/월간 | D14: 세금계산서 발행 | E14: 세금계산서 발행 요청 : 홈택스에서 발급 완료 후 각 폴더에 넣기 -> 완료 노티하면 해당 폴더에서 요청자가 확인 [태경사] - 발행일자 : 매월 1일 - 업체 : 태경사 - 품목명 : AI 솔루션 개발 유지보수 서비스 계약 - 금액 : 300,000 (부가세 별도) - 발행일 : 매월 1일 월정기 - 이메일 : na7060@hanmail.net | F14: 15~20분 / 건 | L14: 수행일자: 매월 1일 (태경사) | M14: 참고: 홈택스에서 세금계산서 발행 ㄴ발급한 세금계산서는 보통 finance 메일에서 확인 가능하나 관련 폴더에 넣어두도록
B15: 경영지원 | C15: 월간 | D15: 법인 서류관리 - 유효기간 있는 것들은 정기적으로 확인 | E15: - 월 1회, 등기부등본, 인감증명서 잔여수량 확인 및 발급 진행 (5개씩 발급, 인감증명서인 경우, 3개월 지난 서류는 사용할 수 없으므로 파기) - 준비물 : 클리어파일, 인감카드, 법인카드 - 장소 : 강남구청 - 사업자등록증, 주주명부 등의 서류도 3개씩 출력 및 보관 - 발급 후, 스캔해서 경영지원 파일 계속해서 업데이트 서류들 요청받을 경우 - 요구되는 발급 기간이 있는지 - 특정 일자 이후 발급본만 취급인지 반드시 확인 | F15: 2시간 / 월 (강남구청 왕복·발급·스캔 포함) | L15: 수행일자: 매월 1일
B16: 경영지원 | C16: 일간 | D16: [확인] 아웃룩 메일 확인 | E16: 매일 아웃룩 메일 확인 및 관리 (finance/sales/hr/contact/marketing/sales/cs) | F16: 20~30분 / 일 | L16: 수행일자: 매일
B17: 경영지원 | C17: 주간 | D17: 전체회의/팀장 주간회의 | E17: 전체회의/부팀장 회의일정 확정 후 팀즈 캘린더 생성 - 전체회의는 매주 화요일 오전 10:30~11:30 - 부팀장 주간회의는 매주 화요일 오후 14:00~15:00 - 매주 대표님 일정 확인 후, 일정 생성 | F17: 15~20분 / 주 (회의 참석 시간 별도) | L17: 수행일자: 매주 주간 팀장/부팀장 회의 - 매주 화요일 10:30 / 주간 전체 회의 - 매주 수요일 10:30 스파크플러스 회의실 예약은 웹/앱으로 2주 전부터 가능 (1시간 1크레딧, 월 57 크레딧) 캘린더에 2주 전 알림 등 생성해두고 미리 예약 | M17: 참고: 팀즈 일정 -> 새 모임 클릭 -> 제목/시간 -> 해당되는 참석자 추가 - 예시) [주간회의][13D] (주)제로스트에이아이 전체회의 / 모든 참석자 추가 - 예시) [13시] 팀별 주간회의 / 부팀장만 추가 - 캘린더 제목은 [시간][회의실] 내용
B18: 경영지원 | C18: 주간 | D18: [가이드] 업무 사용 가이드 및 매뉴얼 업데이트 | E18: ㈜제로스트에이아이 일반 채널에 업로드 되어있는 가이드 및 매뉴얼 업데이트 | F18: 30분~1시간 / 건 (업데이트 사항 있을 때만) | M18: 참고: 업데이트 된 내용 있을 때만 진행하면 됨
B19: 경영지원 | C19: 비정기 | D19: 슬라이드/기획 제작 | E19: 기본 자료 바탕으로 md 파일 만들기 md 파일들 바탕으로 기획안으로 디벨롭 이후 슬라이드/이미지 생성은 클로드 등 툴 활용 | F19: 4~8시간 / 건
B20: 경영지원 | C20: 월간 | D20: [지원] 유관 전시회 서칭 및 리스트업 | E20: 당사 사업과 적합한 전시 서칭 및 리스트업 | F20: 1~2시간 / 월 | L20: 수행일자: 매월 1일 | M20: 참고: 전시 리스트_(주)제로스트에이아이_25.09.03.xlsx
B21: 경영지원 | C21: 비정기 | D21: 나라장터 입찰·전자계약 관리 | E21: 나라장터에 공동인증서 등록 입찰 가능 여부 확인 및 계약서 확인 공공조달 계약 시 전자계약 진행 | F21: 1~2시간 / 건
B22: 경영지원 | C22: 비정기 | D22: 크몽(AX 구축) 계정·문의·세션 등록 | E22: 크몽 계정 확인 및 문의 대응 AX 구축 세션 등록 및 내용 업데이트 | F22: 30분~1시간 / 건
B23: 경영지원 | C23: 비정기 | D23: PG·보증보험 가입 관리 | E23: 페이버스 PG 등록을 위한 보증보험 가입 선금·손해배상 보증보험 가입 (서울보증보험 담당자 문의) | F23: 1~2시간 / 건 (담당자 회신 대기 별도) | L23: 수행일자: 필요시 | M23: 참고: 보증보험증권 가입 메뉴얼
B24: 서비스 관리 | C24: 비정기 | D24: 호텔 제로바타 쇼핑몰 상품 구매 | E24: 판매 물품은 지속적으로 업데이트 및 추가 | F24: 1시간 / 회 | M24: 참고: 제로바타호텔_판매물품정리.xlsx
B25: 서비스 관리 | C25: 비정기 | D25: 호텔 제로바타 상품 관리 및 포장 | E25: 기본 포장 및 관리 매뉴얼은 가이드 참고. 문의사항은 기획팀 또는 대표님 문의 | F25: 1~2시간 / 회 | M25: 참고: 포장 및 배송 프로세스_(주)제로스트에이아이.xlsx
B26: 서비스 관리 | C26: 비정기 | D26: 전자계약·산출내역서 발송 | E26: 기관별 전자계약 발송 및 재발송 산출내역서 작성 후 공유 | F26: 1시간 / 건
B27: 서비스 관리 | C27: 비정기 | D27: 소울리 녹음·데이터 현장 지원 | E27: 소울리 데이터용 녹음 현장 보조 녹음실 관련 지원 필요 시 서포트 (w/ 혜원님) | F27: 4~8시간 / 회 (현장 일정에 따름) | L27: 수행일자: 필요시
B28: 아르바이트 관리 | C28: 비정기 | D28: [인사] 채용공고 관리 | F28: 30분~1시간 / 건
B29: 아르바이트 관리 | C29: 비정기 | D29: [인사] 근로계약서 관리 | F29: 30분 / 건 | L29: * 근무 시간 유동적으로 변경 가능한 점 명시 * 근로계약은 자동 연장이 아니라는 점 명시 * 4대 보험 가입 명시
B30: 아르바이트 관리 | C30: 비정기 | D30: [회계] 외화 환전 | E30: 배송/배달 대행 시 현금 결제하는 경우, 잔돈을 현금으로 거슬러 줘야 하는 이슈 발생 외국인 고객의 외화 현금 결제 하는 경우 대비하여 외화 환전도 필요 다만 대부분의 은행이나 환전소에서는 안해주는 경우가 많음 | F30: 1~2시간 / 회 (은행·환전소 방문 포함) | L30: 수행일자: 최초) 2026.01.14 | M30: 참고: 진행 내역 예시
B31: 아르바이트 관리 | C31: 월간 | D31: [회계] 급여 지출 | F31: 1시간 / 월
B32: 아르바이트 관리 | C32: 주간 | D32: [회계] 현금시재표 관리 | F32: 20~30분 / 주
B33: 영업 지원 | C33: 비정기 | D33: [영업] T/A 영업관리표 업데이트 | E33: 각 시트에 맞게 작성 확인 및 기관 리스트업 | F33: 30분~1시간 / 회 | M33: 참고: 1.. XeroVatar 영업 관리표_(주)제로스트에이아이.xlsx
B34: 영업 지원 | C34: 비정기 | D34: 영업 주간회의 참여 및 회의록 업로드 | E34: 영업파트너사/영업 인력과 주간회의 진행 시 참여하여 회의록 업로드, 제로바타/팔레트 1. 주간회의 채널 참고 | F34: 1.5~2시간 / 회 (회의 1시간 + 회의록 정리) | M34: 참고: 영업 주간회의 회의록 예시
B35: 영업 지원 | C35: 비정기 | D35: 제로바타 소개서 업데이트 | E35: 제로바타/팔레트: 1.일반 채널→공용 제로바타 소개서, 2.전시문화 채널→전시문화기관 버전, 3.호텔 채널→호텔 버전 | F35: 2~4시간 / 건
B36: 영업 지원 | C36: 비정기 | D36: 카드 단말기 사용 | E36: 예전 단말기 : 사용 가이드에 상세한 사용법 작성되어있으며, 주로 키인결제 사용 현재 단말기 : KTR-1200N + 구매 시 가이드 | F36: 10~15분 / 건 | M36: 참고: 9. 카드 단말기 사용 가이드_(주)제로스트에이아이_25.01.16.xlsx
B37: 영업 지원 | C37: 월간 | D37: [공유] 참여 지원사업 현재 진행상황 공유 | E37: 진행 중이거나 지원 완료한 정부지원사업 상세정보 기입 | F37: 1시간 / 월 | L37: 수행일자: 매월 1일 | M37: 참고: 정부지원사업 기본정보_(주)제로스트에이아이_25.04.09 1.xlsx
B38: 영업 지원 | C38: 월간 | D38: 제로바타 월 정기 결제 (카드단말기 키인결제) | E38: GKL 결제 5525-7642-0096-5768 02/27 121 매월 초 키인결제로 590,000 * 2 = 1,180,000원 / 나이스 포스 -> 접속해서 카드결제 전표 출력 가능 (매월 초 GKL에 보내줄 것) xerostN701 doubleN07$ --------------------- 한국족보박물관 4140-2546-5478-6900 01/27 매달 988,000원 : 천 이사님이 소통후 노티줄 것 -> 월 초에 알아서(천 이사 퇴사부터는 경영지원에서 챙기기) | F38: 30분 / 월 | L38: 수행일자: 매월 첫 영업일 ※ 카드번호·계정정보가 포함되어 있으므로 파일 공유 범위 유의 (계정정보 파일로 이관 권장)
B39: 영업 지원 | C39: 주간 | D39: [전달] 영업 리마인드 및 업무 피드백 전달 | E39: 영업 주간회의 내용 토대로 리마인드 및 영업관리표 확인 후 피드백 전달 | F39: 30분~1시간 / 주 | L39: 수행일자: 매주 수요일 | M39: 참고: 영업 리마인드 및 업무 피드백 전달 예시
B40: 영업 지원 | C40: 비정기 | D40: 자사 영업관리 툴(세일즈태스크) 구축 지원 | E40: 자사 영업관리 툴(세일즈태스크) 작업 진행 확인 (w/ 세훈님) | F40: 1~2시간 / 회
B41: 인사 | C41: 비정기 | D41: 퇴사자 발생 | E41: * 사직서 수취 : 가능한 한 금품 청산은 회사에 유리한 일정으로 제안 * 비품/자산 반납 요청 및 인수인계 요청 * 사무실 출입 권한 제한 - 스파크플러스 기준(어드민) * 계정 제한 요청 * 기존 직원 정보 리스트에서 퇴사자 탭으로 이동 * 릭택스에서 상실 신고 요청 (추가 : 퇴사 설문 요청) | F41: 2~3시간 / 건 (퇴사일 당일 처리 기준, 후속 정산 별도)
...

Sheet 채용·입사 프로세스
B1: 채용·입사 프로세스
B2: 원본: '채용, 입사' 시트. 신규 인력 채용 시 순서대로 진행하는 업무 (16건). 예상 소요시간은 1회·1인 기준.
B4: 업무 분야 | C4: 업무 빈도 구분 | D4: 업무명 | E4: 업무 내용 | F4: 예상 소요시간 | G4: 업무 진행상태 | H4: 진행 중 / 결과 | I4: 시작 날짜 | J4: 마감 날짜 | K4: 중요도 | L4: 비고 | M4: 메모
B5: 인사 | C5: 비정기(채용 시) | D5: 채용공고 내용 작성 및 상세페이지 제작 | E5: 1차 채용공고 내용 작성 -> 대표님 컨펌 -> 상세페이지 제작 | F5: 2~3시간 / 직무 | M5: 가이드: 3. 채용공고
B6: 인사 | C6: 비정기(채용 시) | D6: 채용공고 업로드 | E6: 채용공고를 구인구직 사이트에 업로드, 인사 채널 계정 정보 확인 | F6: 30분~1시간 / 직무
B7: 총무 | C7: 비정기(채용 시) | D7: (필요시)[결제] 잡코리아 유료상품 결제 | E7: 채용 진행 또는 유료 공고 이용 시 연락드리면 공고 관리, 할인쿠폰, 서비스제공 등 해주심. 지원자들이 PC/모바일 중 어느걸로 더 조회를 많이 했는지 확인 가능함. 그 옵션에 맞춰 홍보 상품을 구매하는게 좋을듯. | F7: 30분 / 건 | M7: 가이드: 잡코리아 홍보상품 사용내역서_(주)제로스트에이아이_24.10.25.xlsx
B8: 인사 | C8: 비정기(채용 시) | D8: 지원자 선별 리스트 업데이트 | E8: 지원자 조건에 맞춰 리스트 업데이트 진행 -> 대표님에게 플래너로 확인 요청 | F8: 30분~1시간 / 회 | M8: 가이드: 지원자 선별 리스트 예시
B9: 인사 | C9: 비정기(채용 시) | D9: 직무에 맞는 면접 질문 양식 제작 | E9: 직무별 면접 질문 서칭 후 대표님 컨펌. 각 직무별 질문 상이 | F9: 1~2시간 / 직무 | M9: 가이드: 면접 질문양식 제작 예시
B10: 인사 | C10: 비정기(채용 시) | D10: 면접용 회사 소개 PPT 제작 | E10: 면접 진행 시, 회사 소개 후 면접 진행, 직무별 소개 ppt 가 다름 | F10: 2~4시간 / 신규 제작 (기존 자료 업데이트 시 30분) | M10: 가이드: 3. 신규_면접 가이드
B11: 인사 | C11: 비정기(채용 시) | D11: 면접 일정 생성 및 안내 | E11: 입사 확정 인력 가이드에 순서대로 작성되어 있음 | F11: 20~30분 / 인 | M11: 가이드: 입사 확정 인력 가이드_(주)제로스트에이아이_24.10.16.xlsx
B12: 인사 | C12: 비정기(채용 시) | D12: 면접 리마인드 연락 | F12: 10분 / 인
B13: 인사 | C13: 비정기(채용 시) | D13: 면접 진행 | F13: 1시간 / 인
B14: 인사 | C14: 비정기(채용 시) | D14: [연락] 합격/불합격 연락 | F14: 10~15분 / 인
B15: 총무 | C15: 비정기(채용 시) | D15: [구매] 신규인력 물품 구매 및 세팅 | E15: 내부 물품 확인 후 부족한 물품만 추가 구매 | F15: 1~2시간 / 인 (배송기간 별도) | M15: 가이드: 신규인력 물품 세팅.xlsx
B16: 총무 | C16: 비정기(채용 시) | D16: [관리] 자산관리 리스트 업데이트 | E16: 신규 인력 물품 구매 시, 노트북/모니터 등 물품 관리 및 라벨 부착 | F16: 20~30분 / 인 | M16: 가이드: 자산관리 리스트_(주)제로스트에이아이.xlsx
B17: 인사 | C17: 비정기(채용 시) | D17: 신규 인력 사무실 및 업무 규정 안내 | E17: 입사 확정 인력 가이드에 순서대로 작성되어 있음 | F17: 1시간 / 인 | L17: 위워크 관련 내용 수정 필요 | M17: 가이드: 입사 확정 인력 가이드_(주)제로스트에이아이_24.10.16.xlsx
B18: 인사 | C18: 비정기(채용 시) | D18: 근로자 서류 관리 | E18: 근로계약서, 신분증 등 주요 서류 보관 및 업데이트 | F18: 20~30분 / 인 | M18: 가이드: 2. 근로자_장기근무 (정규직, 계약직)
B19: 인사 | C19: 비정기(채용 시) | D19: [작성] 근로계약서 작성 | E19: 신규 인력 입사 시, 당일에 근로계약서 작성 | F19: 30분~1시간 / 인 | M19: 가이드: 근로계약서 작성 체크리스트_(주)제로스트에이아이_24.12.10.xlsx
B20: 인사 | C20: 비정기(채용 시) | D20: 4대보험 신고 (입사 약 1~2주 후) | E20: 릭택스에 4대보험 신고 진행 ** 입사 당일날 진행하지 말것 | F20: 20~30분 / 인 | L20: 입사 당일 진행 금지, 입사 약 1~2주 후 진행

Sheet 이사·법인등기 프로세스
B1: 이사·법인등기 프로세스
B2: 원본: '이사, 법인 등기' 시트. 사무실 이전 시 순서대로 진행하는 업무 (17건). 예상 소요시간은 1회 기준.
B4: 업무 분야 | C4: 업무 빈도 구분 | D4: 업무명 | E4: 업무 내용 | F4: 예상 소요시간 | G4: 업무 진행상태 | H4: 진행 중 / 결과 | I4: 시작 날짜 | J4: 마감 날짜 | K4: 중요도 | L4: 비고 | M4: 메모
B5: 경영지원 | C5: 비정기(이사 시) | D5: 사무실 계약기간 확인 및 연장 여부 문의 | E5: 계약 해지 한달 전, 대표님께 사무실 연장 여부 문의 | F5: 20분 | L5: 계약 해지 1개월 전
B6: 총무 | C6: 비정기(이사 시) | D6: 사무실 비교 리스트 | E6: 사무실 이전 시, 오피스 문의 및 내용 업데이트 | F6: 4~8시간 | M6: 가이드: 사무실 비교 리스트_(주)제로스트에이아이_25.11.17.xlsx
B7: 총무 | C7: 비정기(이사 시) | D7: 사무실 투어 및 계약 | E7: 대표님께서 투어 요청해주시면, 담당자한테 연락해서 투어 일정 예약 | F7: 2~3시간 / 투어 1회 (계약 체결 1~2시간 별도)
B8: 총무 | C8: 비정기(이사 시) | D8: [배치] 사무실 자리 배치도 | E8: 사무실 이전 시, 자리를 정해야하므로 배치도 제작 | F8: 1~2시간 | M8: 가이드: 10인실, 4인실 평면도_(주)제로스트에이아이_25.09.16.pptx
B9: 총무 | C9: 비정기(이사 시) | D9: [정리] 사무실 내부 물품 정리 | E9: 대표님과 논의 후, 물품 정리표 작성 | F9: 4시간 | M9: 가이드: 물품 정리표
B10: 총무 | C10: 비정기(이사 시) | D10: [자산] 중고품 판매 및 물품 정리 | E10: 주로 당근마켓 활용. 판매금액은 대표님과 논의 | F10: 2~3시간 (거래 대기기간 별도)
B11: 총무 | C11: 비정기(이사 시) | D11: [예약] 이사업체 예약 | E11: 이사업체 선별 -> 포장/반포장, 박스 등의 정보 전달 -> 견적서 대표님께 전달 | F11: 1~2시간 | M11: 가이드: 이사업체 견적 리스트_(주)제로스트에이아이_24.11.29.xlsx
B12: 경영지원 | C12: 비정기(이사 시) | D12: [안내] 직원분에게 사무실 관련 내용 안내 | E12: 직원분들께 사무실 안내 및 이사일정 전달 | F12: 30분
B13: 회계 | C13: 비정기(이사 시) | D13: [지출] 보증금, 임대료 등 이용금액 납부 | E13: 납부 일정 확인 및 입금 캡처본 전달 | F13: 20~30분
B14: 경영지원 | C14: 비정기(이사 시) | D14: [반납] 오피스 대여물품 반납 | E14: 사용하던 오피스 제공 물품 반납 | F14: 1시간 | M14: 가이드: 이사 전후 업무 리스트_(주)제로스트에이아이_24.12.26.xlsx
B15: 경영지원 | C15: 비정기(이사 시) | D15: [신청] 법인 등기 변경 신청 | E15: 본점이전 변경 등기 신청, : 2주 내로 변경해야함 | F15: 1~2시간 (법무사 처리기간 별도) | L15: 이전 후 2주 내 신청
B16: 경영지원 | C16: 비정기(이사 시) | D16: [안내] 건물 및 사무실 사용 시, 유의사항 안내 | F16: 30분
B17: 경영지원 | C17: 비정기(이사 시) | D17: [변경] 각종 서류 주소지 변경 | E17: 사업자등록증, 4대보험 사업장 주소지 등 | F17: 2~3시간
B18: 총무 | C18: 비정기(이사 시) | D18: [제작] 법인 명판 주문제작 | E18: 주소 변경으로 인해 명판 주문, 현재 50x30 사이즈 명판 구매 중 | F18: 20~30분 (제작기간 별도)
B19: 경영지원 | C19: 비정기(이사 시) | D19: [변경] 명함, 우편봉투 등 라벨지 주소 변경 | E19: 라벨지_주소 | F19: 30분~1시간
B20: 경영지원 | C20: 비정기(이사 시) | D20: [변경] 아웃룩 전자메일 서명 변경 | E20: 아웃룩 설정 > 서명 클릭 > 주소지 편집 | F20: 10분
B21: 경영지원 | C21: 비정기(이사 시) | D21: [연결] 프린터 연결 | E21: 인쇄 업무가 많으므로, 프린터 연결 필수 | F21: 15~30분 | M21: 가이드: 노트북 초기 세팅 가이드_(주)제로스트에이아이.xlsx

Sheet 요약
B1: 업무 분야 × 빈도별 건수 (업무리스트 시트 기준, 수식 자동 집계)
B3: 업무 분야 | C3: 일간 | D3: 주간 | E3: 월간 | F3: 분기별 | G3: 연간 | H3: 상시 | I3: 비정기 | J3: 합계
B4: 경영지원 | C4: =COUNTIFS(업무리스트!$B$8:$B$113,$B4,업무리스트!$C$8:$C$113,"일간") -> 2 | D4: =COUNTIFS(업무리스트!$B$8:$B$113,$B4,업무리스트!$C$8:$C$113,"주간") -> 5 | E4: =COUNTIFS(업무리스트!$B$8:$B$113,$B4,업무리스트!$C$8:$C$113,"월간")+COUNTIFS(업무리스트!$B$8:$B$113,$B4,업무리스트!$C$8:$C$113,"월 정기") -> 2 | F4: =COUNTIFS(업무리스트!$B$8:$B$113,$B4,업무리스트!$C$8:$C$113,"분기별") -> 0 | G4: =COUNTIFS(업무리스트!$B$8:$B$113,$B4,업무리스트!$C$8:$C$113,"연간") -> 0 | H4: =COUNTIFS(업무리스트!$B$8:$B$113,$B4,업무리스트!$C$8:$C$113,"상시") -> 0 | I4: =COUNTIFS(업무리스트!$B$8:$B$113,$B4,업무리스트!$C$8:$C$113,"비정기") -> 10 | J4: =COUNTIF(업무리스트!$B$8:$B$113,$B4) -> 20
B5: 총무 | C5: =COUNTIFS(업무리스트!$B$8:$B$113,$B5,업무리스트!$C$8:$C$113,"일간") -> 0 | D5: =COUNTIFS(업무리스트!$B$8:$B$113,$B5,업무리스트!$C$8:$C$113,"주간") -> 2 | E5: =COUNTIFS(업무리스트!$B$8:$B$113,$B5,업무리스트!$C$8:$C$113,"월간")+COUNTIFS(업무리스트!$B$8:$B$113,$B5,업무리스트!$C$8:$C$113,"월 정기") -> 5 | F5: =COUNTIFS(업무리스트!$B$8:$B$113,$B5,업무리스트!$C$8:$C$113,"분기별") -> 0 | G5: =COUNTIFS(업무리스트!$B$8:$B$113,$B5,업무리스트!$C$8:$C$113,"연간") -> 0 | H5: =COUNTIFS(업무리스트!$B$8:$B$113,$B5,업무리스트!$C$8:$C$113,"상시") -> 0 | I5: =COUNTIFS(업무리스트!$B$8:$B$113,$B5,업무리스트!$C$8:$C$113,"비정기") -> 13 | J5: =COUNTIF(업무리스트!$B$8:$B$113,$B5) -> 20
B6: 인사 | C6: =COUNTIFS(업무리스트!$B$8:$B$113,$B6,업무리스트!$C$8:$C$113,"일간") -> 3 | D6: =COUNTIFS(업무리스트!$B$8:$B$113,$B6,업무리스트!$C$8:$C$113,"주간") -> 0 | E6: =COUNTIFS(업무리스트!$B$8:$B$113,$B6,업무리스트!$C$8:$C$113,"월간")+COUNTIFS(업무리스트!$B$8:$B$113,$B6,업무리스트!$C$8:$C$113,"월 정기") -> 2 | F6: =COUNTIFS(업무리스트!$B$8:$B$113,$B6,업무리스트!$C$8:$C$113,"분기별") -> 0 | G6: =COUNTIFS(업무리스트!$B$8:$B$113,$B6,업무리스트!$C$8:$C$113,"연간") -> 0 | H6: =COUNTIFS(업무리스트!$B$8:$B$113,$B6,업무리스트!$C$8:$C$113,"상시") -> 1 | I6: =COUNTIFS(업무리스트!$B$8:$B$113,$B6,업무리스트!$C$8:$C$113,"비정기") -> 14 | J6: =COUNTIF(업무리스트!$B$8:$B$113,$B6) -> 20
B7: 회계 | C7: =COUNTIFS(업무리스트!$B$8:$B$113,$B7,업무리스트!$C$8:$C$113,"일간") -> 1 | D7: =COUNTIFS(업무리스트!$B$8:$B$113,$B7,업무리스트!$C$8:$C$113,"주간") -> 1 | E7: =COUNTIFS(업무리스트!$B$8:$B$113,$B7,업무리스트!$C$8:$C$113,"월간")+COUNTIFS(업무리스트!$B$8:$B$113,$B7,업무리스트!$C$8:$C$113,"월 정기") -> 10 | F7: =COUNTIFS(업무리스트!$B$8:$B$113,$B7,업무리스트!$C$8:$C$113,"분기별") -> 1 | G7: =COUNTIFS(업무리스트!$B$8:$B$113,$B7,업무리스트!$C$8:$C$113,"연간") -> 1 | H7: =COUNTIFS(업무리스트!$B$8:$B$113,$B7,업무리스트!$C$8:$C$113,"상시") -> 0 | I7: =COUNTIFS(업무리스트!$B$8:$B$113,$B7,업무리스트!$C$8:$C$113,"비정기") -> 6 | J7: =COUNTIF(업무리스트!$B$8:$B$113,$B7) -> 20
B8: 영업 지원 | C8: =COUNTIFS(업무리스트!$B$8:$B$113,$B8,업무리스트!$C$8:$C$113,"일간") -> 0 | D8: =COUNTIFS(업무리스트!$B$8:$B$113,$B8,업무리스트!$C$8:$C$113,"주간") -> 1 | E8: =COUNTIFS(업무리스트!$B$8:$B$113,$B8,업무리스트!$C$8:$C$113,"월간")+COUNTIFS(업무리스트!$B$8:$B$113,$B8,업무리스트!$C$8:$C$113,"월 정기") -> 2 | F8: =COUNTIFS(업무리스트!$B$8:$B$113,$B8,업무리스트!$C$8:$C$113,"분기별") -> 0 | G8: =COUNTIFS(업무리스트!$B$8:$B$113,$B8,업무리스트!$C$8:$C$113,"연간") -> 0 | H8: =COUNTIFS(업무리스트!$B$8:$B$113,$B8,업무리스트!$C$8:$C$113,"상시") -> 0 | I8: =COUNTIFS(업무리스트!$B$8:$B$113,$B8,업무리스트!$C$8:$C$113,"비정기") -> 6 | J8: =COUNTIF(업무리스트!$B$8:$B$113,$B8) -> 9
B9: 정부지원사업 | C9: =COUNTIFS(업무리스트!$B$8:$B$113,$B9,업무리스트!$C$8:$C$113,"일간") -> 0 | D9: =COUNTIFS(업무리스트!$B$8:$B$113,$B9,업무리스트!$C$8:$C$113,"주간") -> 0 | E9: =COUNTIFS(업무리스트!$B$8:$B$113,$B9,업무리스트!$C$8:$C$113,"월간")+COUNTIFS(업무리스트!$B$8:$B$113,$B9,업무리스트!$C$8:$C$113,"월 정기") -> 1 | F9: =COUNTIFS(업무리스트!$B$8:$B$113,$B9,업무리스트!$C$8:$C$113,"분기별") -> 0 | G9: =COUNTIFS(업무리스트!$B$8:$B$113,$B9,업무리스트!$C$8:$C$113,"연간") -> 0 | H9: =COUNTIFS(업무리스트!$B$8:$B$113,$B9,업무리스트!$C$8:$C$113,"상시") -> 1 | I9: =COUNTIFS(업무리스트!$B$8:$B$113,$B9,업무리스트!$C$8:$C$113,"비정기") -> 0 | J9: =COUNTIF(업무리스트!$B$8:$B$113,$B9) -> 3
B10: 서비스 관리 | C10: =COUNTIFS(업무리스트!$B$8:$B$113,$B10,업무리스트!$C$8:$C$113,"일간") -> 0 | D10: =COUNTIFS(업무리스트!$B$8:$B$113,$B10,업무리스트!$C$8:$C$113,"주간") -> 0 | E10: =COUNTIFS(업무리스트!$B$8:$B$113,$B10,업무리스트!$C$8:$C$113,"월간")+COUNTIFS(업무리스트!$B$8:$B$113,$B10,업무리스트!$C$8:$C$113,"월 정기") -> 1 | F10: =COUNTIFS(업무리스트!$B$8:$B$113,$B10,업무리스트!$C$8:$C$113,"분기별") -> 0 | G10: =COUNTIFS(업무리스트!$B$8:$B$113,$B10,업무리스트!$C$8:$C$113,"연간") -> 0 | H10: =COUNTIFS(업무리스트!$B$8:$B$113,$B10,업무리스트!$C$8:$C$113,"상시") -> 0 | I10: =COUNTIFS(업무리스트!$B$8:$B$113,$B10,업무리스트!$C$8:$C$113,"비정기") -> 5 | J10: =COUNTIF(업무리스트!$B$8:$B$113,$B10) -> 6
B11: 자사 서비스 관리 | C11: =COUNTIFS(업무리스트!$B$8:$B$113,$B11,업무리스트!$C$8:$C$113,"일간") -> 1 | D11: =COUNTIFS(업무리스트!$B$8:$B$113,$B11,업무리스트!$C$8:$C$113,"주간") -> 0 | E11: =COUNTIFS(업무리스트!$B$8:$B$113,$B11,업무리스트!$C$8:$C$113,"월간")+COUNTIFS(업무리스트!$B$8:$B$113,$B11,업무리스트!$C$8:$C$113,"월 정기") -> 0 | F11: =COUNTIFS(업무리스트!$B$8:$B$113,$B11,업무리스트!$C$8:$C$113,"분기별") -> 0 | G11: =COUNTIFS(업무리스트!$B$8:$B$113,$B11,업무리스트!$C$8:$C$113,"연간") -> 0 | H11: =COUNTIFS(업무리스트!$B$8:$B$113,$B11,업무리스트!$C$8:$C$113,"상시") -> 0 | I11: =COUNTIFS(업무리스트!$B$8:$B$113,$B11,업무리스트!$C$8:$C$113,"비정기") -> 2 | J11: =COUNTIF(업무리스트!$B$8:$B$113,$B11) -> 3
B12: 아르바이트 관리 | C12: =COUNTIFS(업무리스트!$B$8:$B$113,$B12,업무리스트!$C$8:$C$113,"일간") -> 0 | D12: =COUNTIFS(업무리스트!$B$8:$B$113,$B12,업무리스트!$C$8:$C$113,"주간") -> 1 | E12: =COUNTIFS(업무리스트!$B$8:$B$113,$B12,업무리스트!$C$8:$C$113,"월간")+COUNTIFS(업무리스트!$B$8:$B$113,$B12,업무리스트!$C$8:$C$113,"월 정기") -> 1 | F12: =COUNTIFS(업무리스트!$B$8:$B$113,$B12,업무리스트!$C$8:$C$113,"분기별") -> 0 | G12: =COUNTIFS(업무리스트!$B$8:$B$113,$B12,업무리스트!$C$8:$C$113,"연간") -> 0 | H12: =COUNTIFS(업무리스트!$B$8:$B$113,$B12,업무리스트!$C$8:$C$113,"상시") -> 0 | I12: =COUNTIFS(업무리스트!$B$8:$B$113,$B12,업무리스트!$C$8:$C$113,"비정기") -> 3 | J12: =COUNTIF(업무리스트!$B$8:$B$113,$B12) -> 5
B13: 합계 | C13: =SUM(C4:C12) -> 7 | D13: =SUM(D4:D12) -> 10 | E13: =SUM(E4:E12) -> 24 | F13: =SUM(F4:F12) -> 1 | G13: =SUM(G4:G12) -> 1 | H13: =SUM(H4:H12) -> 2 | I13: =SUM(I4:I12) -> 59 | J13: =SUM(J4:J12) -> 106
B15: ※ '월간' 열은 '월 정기' 포함. 빈도 표기가 특수한 항목(비정기/월간, 협약 기간 내)은 개별 열에는 집계되지 않고 합계에만 포함.

Sheet 분류 목록
B1: 드롭다운 목록 (업무리스트 시트의 선택 항목은 이 시트를 참조합니다. 항목을 추가하면 드롭다운에도 반영됩니다.)
B2: 업무 분야 | C2: 업무 빈도 구분 | D2: 업무 진행상태 | E2: 중요도
B3: 경영지원 | C3: 일간 | D3: 시작 전 | E3: 긴급
B4: 총무 | C4: 주간 | D4: 진행 중 | E4: 높음
B5: 인사 | C5: 월간 | D5: 피드백 요청 | E5: 보통
B6: 회계 | C6: 분기별 | D6: 완료 | E6: 낮음
B7: 영업 지원 | C7: 연간
B8: 정부지원사업 | C8: 상시
B9: 서비스 관리 | C9: 비정기
B10: 자사 서비스 관리 | C10: 비정기/월간
B11: 아르바이트 관리 | C11: 월 정기
C12: 협약 기간 내
C13: 비정기(채용 시)
C14: 비정기(이사 시)
